Workbook

Sheet LISTA DE PRECIOS
B3: LISTA MAYORISTA
A11: LOS + PEDIDOS NOVEDADES
A13: Linea | B13: Nombre | C13: SKU | D13: EAN | E13: GÉNERO | F13: FORMATO | G13: PRECIO | H13: CANTIDAD
A14: Afnan | B14: Perfume Afnan 9 PM EDP 100ml (Black) Hombre | C14: COS2463 | D14: 6290171002338 | E14: Perfume Hombre | F14: REGULAR | G14: 26351
A15: Afnan | B15: Afnan Zimaya Red Carpet Paragon EDP 100 ml Unisex | C15: COS2943 | D15: 6290171072256 | E15: Perfume Unisex | F15: REGULAR | G15: 14316
A16: Al Haramain | B16: Perfume Al Haramain Amber Oud Aqua Dubai Extrait de Parfum 100 ml | C16: COS4618 | D16: 6291106814873 | E16: Perfume Unisex | F16: REGULAR | G16: 36178 | I16: =IF(H16>0,COUNTIF($H$16:H16,">0"),"")
A17: Al Haramain | B17: Perfume Al Haramain Amber Oud Aqua Dubai Extrait de Parfum 75 ml | C17: COS4619 | D17: 6291106814859 | E17: Perfume Unisex | F17: REGULAR | G17: 33408 | I17: =IF(H17>0,COUNTIF($H$16:H17,">0"),"")
A18: Bharara | B18: Bharara King EDP 150ml. Hombre | C18: COS7251 | D18: 850050062677 | E18: Perfume Hombre | F18: REGULAR | G18: 54892
A19: Armaf | B19: Perfume Odyssey Mandarin Sky Elixir EDP 100 ml Hombre de Armaf | C19: COS5522 | D19: 6295199805022 | E19: Perfume Hombre | F19: REGULAR | G19: 33408
A20: Armaf | B20: Perfume Club de Nuit Untold Sterling Parfum EDP 105 ML Unisex de Armaf | C20: COS2258 | D20: 6294015164176 | E20: Perfume Unisex | F20: REGULAR | G20: 28775
A21: Azzaro | B21: Perfume Azzaro Wanted EDP 100ml. Hombre | C21: COS3606 | D21: 3614273903172 | E21: Perfume Hombre | F21: REGULAR | G21: 40418
A22: Calvin Klein | B22: Perfume CK One EDT 200 ml Unisex Calvin Klein | C22: PDL1174 | D22: 88300107438 | E22: Perfume Unisex | F22: REGULAR | G22: 28168
A23: Cartier | B23: Perfume Cartier Pasha EDT 100 ml | C23: COS4915 | D23: 3432240506306 | E23: Perfume Hombre | F23: REGULAR | G23: 63288
A24: Cartier | B24: Perfume La Panthera EDP 100 ml Cartier | C24: COS7244 | D24: 3432240506641 | E24: Perfume Mujer | F24: REGULAR | G24: 76791
A25: Carolina Herrera | B25: Carolina Herrera CH Men Pasión EDP for Men 100 ml | C25: COS3796 | D25: 8411061055182 | E25: Perfume Hombre | F25: REGULAR | G25: 33149
A26: Carolina Herrera | B26: 212 NYC Men 100ML EDT Hombre Carolina Herrera | C26: PDL1148 | D26: 8411061043868 | E26: Perfume Hombre | F26: REGULAR | G26: 61643
A27: Carolina Herrera | B27: 212 NYC Men 200ML EDT Hombre Carolina Herrera | C27: PDL1149 | D27: 8411061853207 | E27: Perfume Hombre | F27: REGULAR | G27: 90985
A28: Carolina Herrera | B28: Perfume 212 Vip Rosé NYC 212 Cab Limited Edition EDP 80 ml Carolina Herrera | C28: COS6995 | D28: 8411061124413 | E28: Perfume Mujer | F28: REGULAR | G28: 53248
A29: Carolina Herrera | B29: Perfume Bab Boy EDT 200 ml Carolina Herrera Refill | C29: COS6910 | D29: 8411061063415 | E29: Perfume Hombre | F29: REGULAR | G29: 36264
... A40: French Avenue | B40: Perfume Liquid Brun French Avenue EDP 100 ml | C40: COS4197 | D40: 6290360375694 | E40: Perfume Hombre | F40: REGULAR | G40: 29208
A41: French Avenue | B41: Perfume Vulcan Feu EDP 100 ml Unisex French Avenue | C41: COS5260 | D41: 6290360378053 | E41: Perfume Unisex | F41: REGULAR | G41: 33408 | I41: =IF(H41>0,COUNTIF($H$16:H41,">0"),"")
A42: Giorgio Armani | B42: Giorgio Armani Acqua Di Gio EDT 200 ml | C42: 4232 | D42: 3614273955539 | E42: Perfume Hombre | F42: REGULAR | G42: 92460 | I42: =IF(H42>0,COUNTIF($H$16:H42,">0"),"")
A43: Giorgio Armani | B43: Set Perfume Stronger With You Intensely EDP Intense 100 ml + Mini 15 ml Emporio Armani | C43: COS7037 | D43: 3614274822052 | E43: Perfume Hombre | F43: SET | G43: 91072
A44: Hugo Boss | B44: Hugo Man Cantimplora EDT 125ml. Con Celofán | C44: COS728 | D44: 3614229823806 | E44: Perfume Hombre | F44: REGULAR | G44: 34273
A45: Hugo Boss | B45: Set Perfume Boss Bottled EDT 100 ml + Deo 75 ml Hugo Boss | C45: COS6545 | D45: 3616304957741 | E45: Perfume Hombre | F45: SET
A46: Halloween | B46: Perfume Halloween 100ML EDT Mujer Jesus Del Pozo | C46: JESUS01 | D46: 8431754342016 | E46: Perfume Mujer | F46: REGULAR | G46: 25312 | I46: =IF(H46>0,COUNTIF($H$16:H46,">0"),"")
A47: Halloween | B47: Perfume Halloween Man EDT 125 ml Hombre | C47: JESUS04 | D47: 8431754462516 | E47: Perfume Hombre | F47: REGULAR | G47: 25312 | I47: =IF(H47>0,COUNTIF($H$16:H47,">0"),"")
A48: Hermes | B48: Perfume Terre DHermes EDT 200 ml | C48: COS7058 | D48: 3346130013457 | E48: Perfume Hombre | F48: REGULAR | G48: 84754
A49: Jean Paul Gaultier | B49: Jean Paul Gaultier LE MALE (LE PARFUM) Intense EDP 125 ML Hombre | C49: COS1373 | D49: 8435415032315 | E49: Perfume Hombre | F49: REGULAR | G49: 72203
A50: Jean Paul Gaultier | B50: Perfume Jean Paul Gaultier Scandal Le Parfum EDP Intense Pour Homme 100 ml Recargable | C50: COS3089 | D50: 8435415065191 | E50: Perfume Hombre | F50: REGULAR | G50: 92024
A51: Jo Milano | B51: Perfume Emerald Game of Spades Parfum 90 ml de Jo Milano | C51: COS5608 | D51: 850051043354 | E51: Perfume Unisex | F51: REGULAR | G51: 51517
A52: Jo Milano | B52: Perfume Game Of Spades All-In Parfum 100 ml Jo Milano | C52: COS6810 | D52: 850051043583 | E52: Perfume Unisex | F52: REGULAR | G52: 64586
A53: Lattafa | B53: Perfume ASAD de Lattafa EDP 100 ML | C53: COS2099 | D53: 6291108735411 | E53: Perfume Hombre | F53: REGULAR | G53: 20549
A54: Lattafa | B54: Perfume Asad Elixir 100 ml Lattafa | C54: COS6068 | D54: 6290362346548 | E54: Perfume Hombre | F54: REGULAR | G54: 28948
A55: Lattafa | B55: Perfume Atlas EDP 55 ml de Lattafa | C55: COS5612 | D55: 6290360593722 | E55: Perfume Unisex | F55: REGULAR | G55: 21504
A56: Lattafa | B56: Perfume Badee Al Oud For Glory de Lattafa EDP 100 ML Unisex | C56: COS1933 | D56: 6291107458328 | E56: Perfume Unisex | F56: REGULAR | G56: 19250
A57: Lacoste | B57: Perfume Touch Of Pink 90ML EDT Mujer | C57: LAC2 | D57: 3386460149440 | E57: Perfume Mujer | F57: REGULAR | G57: 26784 | I57: =IF(H57>0,COUNTIF($H$16:H57,">0"),"")
A58: Lacoste | B58: Lacoste L.12.12 Blanc EDT 50 ML Hombre COS2201 | C58: COS2201 | D58: 737052895956 | E58: Perfume Hombre | F58: REGULAR | G58: 24274
A59: Lancôme | B59: Lancôme La Vie Est Belle Rose Extraordinaire EDP Florale 100 ml | C59: COS4105 | D59: 3614274104370 | E59: Perfume Mujer | F59: REGULAR | G59: 77742
A60: Lancôme | B60: Perfume Idole EDP 100 ml Recargable - Refill Lancôme Mujer | C60: COS172 | D60: 3614273069175 | E60: Perfume Mujer | F60: REGULAR | G60: 72982
...

Sheet PEDIDO
B3: PEDIDO MAYORISTA MAYORISTA
A11: CLIENTE | D11: FECHA:
A12: RUT:
A13: CORREO:
A14: NUMERO DE CONTACTO:
A15: Linea | B15: Nombre | C15: SKU | D15: EAN | E15: GÉNERO | F15: FORMATO | G15: PRECIO | H15: CANTIDAD | I15: SUBTOTAL
A16: =IFERROR(INDEX('LISTA DE PRECIOS'!A$16:A$1318,MATCH(1,'LISTA DE PRECIOS'!$I$16:$I$1318,0)),"") | B16: =IFERROR(INDEX('LISTA DE PRECIOS'!B$16:B$1318,MATCH(1,'LISTA DE PRECIOS'!$I$16:$I$1318,0)),"") | C16: =IFERROR(INDEX('LISTA DE PRECIOS'!C$16:C$1318,MATCH(1,'LISTA DE PRECIOS'!$I$16:$I$1318,0)),"") | D16: =IFERROR(INDEX('LISTA DE PRECIOS'!D$16:D$1318,MATCH(1,'LISTA DE PRECIOS'!$I$16:$I$1318,0)),"") | E16: =IFERROR(INDEX('LISTA DE PRECIOS'!E$16:E$1318,MATCH(1,'LISTA DE PRECIOS'!$I$16:$I$1318,0)),"") | F16: =IFERROR(INDEX('LISTA DE PRECIOS'!F$16:F$1318,MATCH(1,'LISTA DE PRECIOS'!$I$16:$I$1318,0)),"") | G16: =IFERROR(INDEX('LISTA DE PRECIOS'!G$16:G$1318,MATCH(1,'LISTA DE PRECIOS'!$I$16:$I$1318,0)),"") | H16: =IFERROR(INDEX('LISTA DE PRECIOS'!H$16:H$1318,MATCH(1,'LISTA DE PRECIOS'!$I$16:$I$1318,0)),"") | I16: =IF(OR(G16="",H16=""),"",G16*H16)
A17: =IFERROR(INDEX('LISTA DE PRECIOS'!A$16:A$1318,MATCH(2,'LISTA DE PRECIOS'!$I$16:$I$1318,0)),"") | B17: =IFERROR(INDEX('LISTA DE PRECIOS'!B$16:B$1318,MATCH(2,'LISTA DE PRECIOS'!$I$16:$I$1318,0)),"") | C17: =IFERROR(INDEX('LISTA DE PRECIOS'!C$16:C$1318,MATCH(2,'LISTA DE PRECIOS'!$I$16:$I$1318,0)),"") | D17: =IFERROR(INDEX('LISTA DE PRECIOS'!D$16:D$1318,MATCH(2,'LISTA DE PRECIOS'!$I$16:$I$1318,0)),"") | E17: =IFERROR(INDEX('LISTA DE PRECIOS'!E$16:E$1318,MATCH(2,'LISTA DE PRECIOS'!$I$16:$I$1318,0)),"") | F17: =IFERROR(INDEX('LISTA DE PRECIOS'!F$16:F$1318,MATCH(2,'LISTA DE PRECIOS'!$I$16:$I$1318,0)),"") | G17: =IFERROR(INDEX('LISTA DE PRECIOS'!G$16:G$1318,MATCH(2,'LISTA DE PRECIOS'!$I$16:$I$1318,0)),"") | H17: =IFERROR(INDEX('LISTA DE PRECIOS'!H$16:H$1318,MATCH(2,'LISTA DE PRECIOS'!$I$16:$I$1318,0)),"") | I17: =IF(OR(G17="",H17=""),"",G17*H17)
A18: =IFERROR(INDEX('LISTA DE PRECIOS'!A$16:A$1318,MATCH(3,'LISTA DE PRECIOS'!$I$16:$I$1318,0)),"") | B18: =IFERROR(INDEX('LISTA DE PRECIOS'!B$16:B$1318,MATCH(3,'LISTA DE PRECIOS'!$I$16:$I$1318,0)),"") | C18: =IFERROR(INDEX('LISTA DE PRECIOS'!C$16:C$1318,MATCH(3,'LISTA DE PRECIOS'!$I$16:$I$1318,0)),"") | D18: =IFERROR(INDEX('LISTA DE PRECIOS'!D$16:D$1318,MATCH(3,'LISTA DE PRECIOS'!$I$16:$I$1318,0)),"") | E18: =IFERROR(INDEX('LISTA DE PRECIOS'!E$16:E$1318,MATCH(3,'LISTA DE PRECIOS'!$I$16:$I$1318,0)),"") | F18: =IFERROR(INDEX('LISTA DE PRECIOS'!F$16:F$1318,MATCH(3,'LISTA DE PRECIOS'!$I$16:$I$1318,0)),"") | G18: =IFERROR(INDEX('LISTA DE PRECIOS'!G$16:G$1318,MATCH(3,'LISTA DE PRECIOS'!$I$16:$I$1318,0)),"") | H18: =IFERROR(INDEX('LISTA DE PRECIOS'!H$16:H$1318,MATCH(3,'LISTA DE PRECIOS'!$I$16:$I$1318,0)),"") | I18: =IF(OR(G18="",H18=""),"",G18*H18)
A19: =IFERROR(INDEX('LISTA DE PRECIOS'!A$16:A$1318,MATCH(4,'LISTA DE PRECIOS'!$I$16:$I$1318,0)),"") | B19: =IFERROR(INDEX('LISTA DE PRECIOS'!B$16:B$1318,MATCH(4,'LISTA DE PRECIOS'!$I$16:$I$1318,0)),"") | C19: =IFERROR(INDEX('LISTA DE PRECIOS'!C$16:C$1318,MATCH(4,'LISTA DE PRECIOS'!$I$16:$I$1318,0)),"") | D19: =IFERROR(INDEX('LISTA DE PRECIOS'!D$16:D$1318,MATCH(4,'LISTA DE PRECIOS'!$I$16:$I$1318,0)),"") | E19: =IFERROR(INDEX('LISTA DE PRECIOS'!E$16:E$1318,MATCH(4,'LISTA DE PRECIOS'!$I$16:$I$1318,0)),"") | F19: =IFERROR(INDEX('LISTA DE PRECIOS'!F$16:F$1318,MATCH(4,'LISTA DE PRECIOS'!$I$16:$I$1318,0)),"") | G19: =IFERROR(INDEX('LISTA DE PRECIOS'!G$16:G$1318,MATCH(4,'LISTA DE PRECIOS'!$I$16:$I$1318,0)),"") | H19: =IFERROR(INDEX('LISTA DE PRECIOS'!H$16:H$1318,MATCH(4,'LISTA DE PRECIOS'!$I$16:$I$1318,0)),"") | I19: =IF(OR(G19="",H19=""),"",G19*H19)
A20: =IFERROR(INDEX('LISTA DE PRECIOS'!A$16:A$1318,MATCH(5,'LISTA DE PRECIOS'!$I$16:$I$1318,0)),"") | B20: =IFERROR(INDEX('LISTA DE PRECIOS'!B$16:B$1318,MATCH(5,'LISTA DE PRECIOS'!$I$16:$I$1318,0)),"") | C20: =IFERROR(INDEX('LISTA DE PRECIOS'!C$16:C$1318,MATCH(5,'LISTA DE PRECIOS'!$I$16:$I$1318,0)),"") | D20: =IFERROR(INDEX('LISTA DE PRECIOS'!D$16:D$1318,MATCH(5,'LISTA DE PRECIOS'!$I$16:$I$1318,0)),"") | E20: =IFERROR(INDEX('LISTA DE PRECIOS'!E$16:E$1318,MATCH(5,'LISTA DE PRECIOS'!$I$16:$I$1318,0)),"") | F20: =IFERROR(INDEX('LISTA DE PRECIOS'!F$16:F$1318,MATCH(5,'LISTA DE PRECIOS'!$I$16:$I$1318,0)),"") | G20: =IFERROR(INDEX('LISTA DE PRECIOS'!G$16:G$1318,MATCH(5,'LISTA DE PRECIOS'!$I$16:$I$1318,0)),"") | H20: =IFERROR(INDEX('LISTA DE PRECIOS'!H$16:H$1318,MATCH(5,'LISTA DE PRECIOS'!$I$16:$I$1318,0)),"") | I20: =IF(OR(G20="",H20=""),"",G20*H20)
A21: =IFERROR(INDEX('LISTA DE PRECIOS'!A$16:A$1318,MATCH(6,'LISTA DE PRECIOS'!$I$16:$I$1318,0)),"") | B21: =IFERROR(INDEX('LISTA DE PRECIOS'!B$16:B$1318,MATCH(6,'LISTA DE PRECIOS'!$I$16:$I$1318,0)),"") | C21: =IFERROR(INDEX('LISTA DE PRECIOS'!C$16:C$1318,MATCH(6,'LISTA DE PRECIOS'!$I$16:$I$1318,0)),"") | D21: =IFERROR(INDEX('LISTA DE PRECIOS'!D$16:D$1318,MATCH(6,'LISTA DE PRECIOS'!$I$16:$I$1318,0)),"") | E21: =IFERROR(INDEX('LISTA DE PRECIOS'!E$16:E$1318,MATCH(6,'LISTA DE PRECIOS'!$I$16:$I$1318,0)),"") | F21: =IFERROR(INDEX('LISTA DE PRECIOS'!F$16:F$1318,MATCH(6,'LISTA DE PRECIOS'!$I$16:$I$1318,0)),"") | G21: =IFERROR(INDEX('LISTA DE PRECIOS'!G$16:G$1318,MATCH(6,'LISTA DE PRECIOS'!$I$16:$I$1318,0)),"") | H21: =IFERROR(INDEX('LISTA DE PRECIOS'!H$16:H$1318,MATCH(6,'LISTA DE PRECIOS'!$I$16:$I$1318,0)),"") | I21: =IF(OR(G21="",H21=""),"",G21*H21)
A22: =IFERROR(INDEX('LISTA DE PRECIOS'!A$16:A$1318,MATCH(7,'LISTA DE PRECIOS'!$I$16:$I$1318,0)),"") | B22: =IFERROR(INDEX('LISTA DE PRECIOS'!B$16:B$1318,MATCH(7,'LISTA DE PRECIOS'!$I$16:$I$1318,0)),"") | C22: =IFERROR(INDEX('LISTA DE PRECIOS'!C$16:C$1318,MATCH(7,'LISTA DE PRECIOS'!$I$16:$I$1318,0)),"") | D22: =IFERROR(INDEX('LISTA DE PRECIOS'!D$16:D$1318,MATCH(7,'LISTA DE PRECIOS'!$I$16:$I$1318,0)),"") | E22: =IFERROR(INDEX('LISTA DE PRECIOS'!E$16:E$1318,MATCH(7,'LISTA DE PRECIOS'!$I$16:$I$1318,0)),"") | F22: =IFERROR(INDEX('LISTA DE PRECIOS'!F$16:F$1318,MATCH(7,'LISTA DE PRECIOS'!$I$16:$I$1318,0)),"") | G22: =IFERROR(INDEX('LISTA DE PRECIOS'!G$16:G$1318,MATCH(7,'LISTA DE PRECIOS'!$I$16:$I$1318,0)),"") | H22: =IFERROR(INDEX('LISTA DE PRECIOS'!H$16:H$1318,MATCH(7,'LISTA DE PRECIOS'!$I$16:$I$1318,0)),"") | I22: =IF(OR(G22="",H22=""),"",G22*H22)
A23: =IFERROR(INDEX('LISTA DE PRECIOS'!A$16:A$1318,MATCH(8,'LISTA DE PRECIOS'!$I$16:$I$1318,0)),"") | B23: =IFERROR(INDEX('LISTA DE PRECIOS'!B$16:B$1318,MATCH(8,'LISTA DE PRECIOS'!$I$16:$I$1318,0)),"") | C23: =IFERROR(INDEX('LISTA DE PRECIOS'!C$16:C$1318,MATCH(8,'LISTA DE PRECIOS'!$I$16:$I$1318,0)),"") | D23: =IFERROR(INDEX('LISTA DE PRECIOS'!D$16:D$1318,MATCH(8,'LISTA DE PRECIOS'!$I$16:$I$1318,0)),"") | E23: =IFERROR(INDEX('LISTA DE PRECIOS'!E$16:E$1318,MATCH(8,'LISTA DE PRECIOS'!$I$16:$I$1318,0)),"") | F23: =IFERROR(INDEX('LISTA DE PRECIOS'!F$16:F$1318,MATCH(8,'LISTA DE PRECIOS'!$I$16:$I$1318,0)),"") | G23: =IFERROR(INDEX('LISTA DE PRECIOS'!G$16:G$1318,MATCH(8,'LISTA DE PRECIOS'!$I$16:$I$1318,0)),"") | H23: =IFERROR(INDEX('LISTA DE PRECIOS'!H$16:H$1318,MATCH(8,'LISTA DE PRECIOS'!$I$16:$I$1318,0)),"") | I23: =IF(OR(G23="",H23=""),"",G23*H23)
A24: =IFERROR(INDEX('LISTA DE PRECIOS'!A$16:A$1318,MATCH(9,'LISTA DE PRECIOS'!$I$16:$I$1318,0)),"") | B24: =IFERROR(INDEX('LISTA DE PRECIOS'!B$16:B$1318,MATCH(9,'LISTA DE PRECIOS'!$I$16:$I$1318,0)),"") | C24: =IFERROR(INDEX('LISTA DE PRECIOS'!C$16:C$1318,MATCH(9,'LISTA DE PRECIOS'!$I$16:$I$1318,0)),"") | D24: =IFERROR(INDEX('LISTA DE PRECIOS'!D$16:D$1318,MATCH(9,'LISTA DE PRECIOS'!$I$16:$I$1318,0)),"") | E24: =IFERROR(INDEX('LISTA DE PRECIOS'!E$16:E$1318,MATCH(9,'LISTA DE PRECIOS'!$I$16:$I$1318,0)),"") | F24: =IFERROR(INDEX('LISTA DE PRECIOS'!F$16:F$1318,MATCH(9,'LISTA DE PRECIOS'!$I$16:$I$1318,0)),"") | G24: =IFERROR(INDEX('LISTA DE PRECIOS'!G$16:G$1318,MATCH(9,'LISTA DE PRECIOS'!$I$16:$I$1318,0)),"") | H24: =IFERROR(INDEX('LISTA DE PRECIOS'!H$16:H$1318,MATCH(9,'LISTA DE PRECIOS'!$I$16:$I$1318,0)),"") | I24: =IF(OR(G24="",H24=""),"",G24*H24)
A25: =IFERROR(INDEX('LISTA DE PRECIOS'!A$16:A$1318,MATCH(10,'LISTA DE PRECIOS'!$I$16:$I$1318,0)),"") | B25: =IFERROR(INDEX('LISTA DE PRECIOS'!B$16:B$1318,MATCH(10,'LISTA DE PRECIOS'!$I$16:$I$1318,0)),"") | C25: =IFERROR(INDEX('LISTA DE PRECIOS'!C$16:C$1318,MATCH(10,'LISTA DE PRECIOS'!$I$16:$I$1318,0)),"") | D25: =IFERROR(INDEX('LISTA DE PRECIOS'!D$16:D$1318,MATCH(10,'LISTA DE PRECIOS'!$I$16:$I$1318,0)),"") | E25: =IFERROR(INDEX('LISTA DE PRECIOS'!E$16:E$1318,MATCH(10,'LISTA DE PRECIOS'!$I$16:$I$1318,0)),"") | F25: =IFERROR(INDEX('LISTA DE PRECIOS'!F$16:F$1318,MATCH(10,'LISTA DE PRECIOS'!$I$16:$I$1318,0)),"") | G25: =IFERROR(INDEX('LISTA DE PRECIOS'!G$16:G$1318,MATCH(10,'LISTA DE PRECIOS'!$I$16:$I$1318,0)),"") | H25: =IFERROR(INDEX('LISTA DE PRECIOS'!H$16:H$1318,MATCH(10,'LISTA DE PRECIOS'!$I$16:$I$1318,0)),"") | I25: =IF(OR(G25="",H25=""),"",G25*H25)
A26: =IFERROR(INDEX('LISTA DE PRECIOS'!A$16:A$1318,MATCH(11,'LISTA DE PRECIOS'!$I$16:$I$1318,0)),"") | B26: =IFERROR(INDEX('LISTA DE PRECIOS'!B$16:B$1318,MATCH(11,'LISTA DE PRECIOS'!$I$16:$I$1318,0)),"") | C26: =IFERROR(INDEX('LISTA DE PRECIOS'!C$16:C$1318,MATCH(11,'LISTA DE PRECIOS'!$I$16:$I$1318,0)),"") | D26: =IFERROR(INDEX('LISTA DE PRECIOS'!D$16:D$1318,MATCH(11,'LISTA DE PRECIOS'!$I$16:$I$1318,0)),"") | E26: =IFERROR(INDEX('LISTA DE PRECIOS'!E$16:E$1318,MATCH(11,'LISTA DE PRECIOS'!$I$16:$I$1318,0)),"") | F26: =IFERROR(INDEX('LISTA DE PRECIOS'!F$16:F$1318,MATCH(11,'LISTA DE PRECIOS'!$I$16:$I$1318,0)),"") | G26: =IFERROR(INDEX('LISTA DE PRECIOS'!G$16:G$1318,MATCH(11,'LISTA DE PRECIOS'!$I$16:$I$1318,0)),"") | H26: =IFERROR(INDEX('LISTA DE PRECIOS'!H$16:H$1318,MATCH(11,'LISTA DE PRECIOS'!$I$16:$I$1318,0)),"") | I26: =IF(OR(G26="",H26=""),"",G26*H26)
A27: =IFERROR(INDEX('LISTA DE PRECIOS'!A$16:A$1318,MATCH(12,'LISTA DE PRECIOS'!$I$16:$I$1318,0)),"") | B27: =IFERROR(INDEX('LISTA DE PRECIOS'!B$16:B$1318,MATCH(12,'LISTA DE PRECIOS'!$I$16:$I$1318,0)),"") | C27: =IFERROR(INDEX('LISTA DE PRECIOS'!C$16:C$1318,MATCH(12,'LISTA DE PRECIOS'!$I$16:$I$1318,0)),"") | D27: =IFERROR(INDEX('LISTA DE PRECIOS'!D$16:D$1318,MATCH(12,'LISTA DE PRECIOS'!$I$16:$I$1318,0)),"") | E27: =IFERROR(INDEX('LISTA DE PRECIOS'!E$16:E$1318,MATCH(12,'LISTA DE PRECIOS'!$I$16:$I$1318,0)),"") | F27: =IFERROR(INDEX('LISTA DE PRECIOS'!F$16:F$1318,MATCH(12,'LISTA DE PRECIOS'!$I$16:$I$1318,0)),"") | G27: =IFERROR(INDEX('LISTA DE PRECIOS'!G$16:G$1318,MATCH(12,'LISTA DE PRECIOS'!$I$16:$I$1318,0)),"") | H27: =IFERROR(INDEX('LISTA DE PRECIOS'!H$16:H$1318,MATCH(12,'LISTA DE PRECIOS'!$I$16:$I$1318,0)),"") | I27: =IF(OR(G27="",H27=""),"",G27*H27)
A28: =IFERROR(INDEX('LISTA DE PRECIOS'!A$16:A$1318,MATCH(13,'LISTA DE PRECIOS'!$I$16:$I$1318,0)),"") | B28: =IFERROR(INDEX('LISTA DE PRECIOS'!B$16:B$1318,MATCH(13,'LISTA DE PRECIOS'!$I$16:$I$1318,0)),"") | C28: =IFERROR(INDEX('LISTA DE PRECIOS'!C$16:C$1318,MATCH(13,'LISTA DE PRECIOS'!$I$16:$I$1318,0)),"") | D28: =IFERROR(INDEX('LISTA DE PRECIOS'!D$16:D$1318,MATCH(13,'LISTA DE PRECIOS'!$I$16:$I$1318,0)),"") | E28: =IFERROR(INDEX('LISTA DE PRECIOS'!E$16:E$1318,MATCH(13,'LISTA DE PRECIOS'!$I$16:$I$1318,0)),"") | F28: =IFERROR(INDEX('LISTA DE PRECIOS'!F$16:F$1318,MATCH(13,'LISTA DE PRECIOS'!$I$16:$I$1318,0)),"") | G28: =IFERROR(INDEX('LISTA DE PRECIOS'!G$16:G$1318,MATCH(13,'LISTA DE PRECIOS'!$I$16:$I$1318,0)),"") | H28: =IFERROR(INDEX('LISTA DE PRECIOS'!H$16:H$1318,MATCH(13,'LISTA DE PRECIOS'!$I$16:$I$1318,0)),"") | I28: =IF(OR(G28="",H28=""),"",G28*H28)
A29: =IFERROR(INDEX('LISTA DE PRECIOS'!A$16:A$1318,MATCH(14,'LISTA DE PRECIOS'!$I$16:$I$1318,0)),"") | B29: =IFERROR(INDEX('LISTA DE PRECIOS'!B$16:B$1318,MATCH(14,'LISTA DE PRECIOS'!$I$16:$I$1318,0)),"") | C29: =IFERROR(INDEX('LISTA DE PRECIOS'!C$16:C$1318,MATCH(14,'LISTA DE PRECIOS'!$I$16:$I$1318,0)),"") | D29: =IFERROR(INDEX('LISTA DE PRECIOS'!D$16:D$1318,MATCH(14,'LISTA DE PRECIOS'!$I$16:$I$1318,0)),"") | E29: =IFERROR(INDEX('LISTA DE PRECIOS'!E$16:E$1318,MATCH(14,'LISTA DE PRECIOS'!$I$16:$I$1318,0)),"") | F29: =IFERROR(INDEX('LISTA DE PRECIOS'!F$16:F$1318,MATCH(14,'LISTA DE PRECIOS'!$I$16:$I$1318,0)),"") | G29: =IFERROR(INDEX('LISTA DE PRECIOS'!G$16:G$1318,MATCH(14,'LISTA DE PRECIOS'!$I$16:$I$1318,0)),"") | H29: =IFERROR(INDEX('LISTA DE PRECIOS'!H$16:H$1318,MATCH(14,'LISTA DE PRECIOS'!$I$16:$I$1318,0)),"") | I29: =IF(OR(G29="",H29=""),"",G29*H29)
A30: =IFERROR(INDEX('LISTA DE PRECIOS'!A$16:A$1318,MATCH(15,'LISTA DE PRECIOS'!$I$16:$I$1318,0)),"") | B30: =IFERROR(INDEX('LISTA DE PRECIOS'!B$16:B$1318,MATCH(15,'LISTA DE PRECIOS'!$I$16:$I$1318,0)),"") | C30: =IFERROR(INDEX('LISTA DE PRECIOS'!C$16:C$1318,MATCH(15,'LISTA DE PRECIOS'!$I$16:$I$1318,0)),"") | D30: =IFERROR(INDEX('LISTA DE PRECIOS'!D$16:D$1318,MATCH(15,'LISTA DE PRECIOS'!$I$16:$I$1318,0)),"") | E30: =IFERROR(INDEX('LISTA DE PRECIOS'!E$16:E$1318,MATCH(15,'LISTA DE PRECIOS'!$I$16:$I$1318,0)),"") | F30: =IFERROR(INDEX('LISTA DE PRECIOS'!F$16:F$1318,MATCH(15,'LISTA DE PRECIOS'!$I$16:$I$1318,0)),"") | G30: =IFERROR(INDEX('LISTA DE PRECIOS'!G$16:G$1318,MATCH(15,'LISTA DE PRECIOS'!$I$16:$I$1318,0)),"") | H30: =IFERROR(INDEX('LISTA DE PRECIOS'!H$16:H$1318,MATCH(15,'LISTA DE PRECIOS'!$I$16:$I$1318,0)),"") | I30: =IF(OR(G30="",H30=""),"",G30*H30)
A31: =IFERROR(INDEX('LISTA DE PRECIOS'!A$16:A$1318,MATCH(16,'LISTA DE PRECIOS'!$I$16:$I$1318,0)),"") | B31: =IFERROR(INDEX('LISTA DE PRECIOS'!B$16:B$1318,MATCH(16,'LISTA DE PRECIOS'!$I$16:$I$1318,0)),"") | C31: =IFERROR(INDEX('LISTA DE PRECIOS'!C$16:C$1318,MATCH(16,'LISTA DE PRECIOS'!$I$16:$I$1318,0)),"") | D31: =IFERROR(INDEX('LISTA DE PRECIOS'!D$16:D$1318,MATCH(16,'LISTA DE PRECIOS'!$I$16:$I$1318,0)),"") | E31: =IFERROR(INDEX('LISTA DE PRECIOS'!E$16:E$1318,MATCH(16,'LISTA DE PRECIOS'!$I$16:$I$1318,0)),"") | F31: =IFERROR(INDEX('LISTA DE PRECIOS'!F$16:F$1318,MATCH(16,'LISTA DE PRECIOS'!$I$16:$I$1318,0)),"") | G31: =IFERROR(INDEX('LISTA DE PRECIOS'!G$16:G$1318,MATCH(16,'LISTA DE PRECIOS'!$I$16:$I$1318,0)),"") | H31: =IFERROR(INDEX('LISTA DE PRECIOS'!H$16:H$1318,MATCH(16,'LISTA DE PRECIOS'!$I$16:$I$1318,0)),"") | I31: =IF(OR(G31="",H31=""),"",G31*H31)
A32: =IFERROR(INDEX('LISTA DE PRECIOS'!A$16:A$1318,MATCH(17,'LISTA DE PRECIOS'!$I$16:$I$1318,0)),"") | B32: =IFERROR(INDEX('LISTA DE PRECIOS'!B$16:B$1318,MATCH(17,'LISTA DE PRECIOS'!$I$16:$I$1318,0)),"") | C32: =IFERROR(INDEX('LISTA DE PRECIOS'!C$16:C$1318,MATCH(17,'LISTA DE PRECIOS'!$I$16:$I$1318,0)),"") | D32: =IFERROR(INDEX('LISTA DE PRECIOS'!D$16:D$1318,MATCH(17,'LISTA DE PRECIOS'!$I$16:$I$1318,0)),"") | E32: =IFERROR(INDEX('LISTA DE PRECIOS'!E$16:E$1318,MATCH(17,'LISTA DE PRECIOS'!$I$16:$I$1318,0)),"") | F32: =IFERROR(INDEX('LISTA DE PRECIOS'!F$16:F$1318,MATCH(17,'LISTA DE PRECIOS'!$I$16:$I$1318,0)),"") | G32: =IFERROR(INDEX('LISTA DE PRECIOS'!G$16:G$1318,MATCH(17,'LISTA DE PRECIOS'!$I$16:$I$1318,0)),"") | H32: =IFERROR(INDEX('LISTA DE PRECIOS'!H$16:H$1318,MATCH(17,'LISTA DE PRECIOS'!$I$16:$I$1318,0)),"") | I32: =IF(OR(G32="",H32=""),"",G32*H32)
A33: =IFERROR(INDEX('LISTA DE PRECIOS'!A$16:A$1318,MATCH(18,'LISTA DE PRECIOS'!$I$16:$I$1318,0)),"") | B33: =IFERROR(INDEX('LISTA DE PRECIOS'!B$16:B$1318,MATCH(18,'LISTA DE PRECIOS'!$I$16:$I$1318,0)),"") | C33: =IFERROR(INDEX('LISTA DE PRECIOS'!C$16:C$1318,MATCH(18,'LISTA DE PRECIOS'!$I$16:$I$1318,0)),"") | D33: =IFERROR(INDEX('LISTA DE PRECIOS'!D$16:D$1318,MATCH(18,'LISTA DE PRECIOS'!$I$16:$I$1318,0)),"") | E33: =IFERROR(INDEX('LISTA DE PRECIOS'!E$16:E$1318,MATCH(18,'LISTA DE PRECIOS'!$I$16:$I$1318,0)),"") | F33: =IFERROR(INDEX('LISTA DE PRECIOS'!F$16:F$1318,MATCH(18,'LISTA DE PRECIOS'!$I$16:$I$1318,0)),"") | G33: =IFERROR(INDEX('LISTA DE PRECIOS'!G$16:G$1318,MATCH(18,'LISTA DE PRECIOS'!$I$16:$I$1318,0)),"") | H33: =IFERROR(INDEX('LISTA DE PRECIOS'!H$16:H$1318,MATCH(18,'LISTA DE PRECIOS'!$I$16:$I$1318,0)),"") | I33: =IF(OR(G33="",H33=""),"",G33*H33)
A34: =IFERROR(INDEX('LISTA DE PRECIOS'!A$16:A$1318,MATCH(19,'LISTA DE PRECIOS'!$I$16:$I$1318,0)),"") | B34: =IFERROR(INDEX('LISTA DE PRECIOS'!B$16:B$1318,MATCH(19,'LISTA DE PRECIOS'!$I$16:$I$1318,0)),"") | C34: =IFERROR(INDEX('LISTA DE PRECIOS'!C$16:C$1318,MATCH(19,'LISTA DE PRECIOS'!$I$16:$I$1318,0)),"") | D34: =IFERROR(INDEX('LISTA DE PRECIOS'!D$16:D$1318,MATCH(19,'LISTA DE PRECIOS'!$I$16:$I$1318,0)),"") | E34: =IFERROR(INDEX('LISTA DE PRECIOS'!E$16:E$1318,MATCH(19,'LISTA DE PRECIOS'!$I$16:$I$1318,0)),"") | F34: =IFERROR(INDEX('LISTA DE PRECIOS'!F$16:F$1318,MATCH(19,'LISTA DE PRECIOS'!$I$16:$I$1318,0)),"") | G34: =IFERROR(INDEX('LISTA DE PRECIOS'!G$16:G$1318,MATCH(19,'LISTA DE PRECIOS'!$I$16:$I$1318,0)),"") | H34: =IFERROR(INDEX('LISTA DE PRECIOS'!H$16:H$1318,MATCH(19,'LISTA DE PRECIOS'!$I$16:$I$1318,0)),"") | I34: =IF(OR(G34="",H34=""),"",G34*H34)
A35: =IFERROR(INDEX('LISTA DE PRECIOS'!A$16:A$1318,MATCH(20,'LISTA DE PRECIOS'!$I$16:$I$1318,0)),"") | B35: =IFERROR(INDEX('LISTA DE PRECIOS'!B$16:B$1318,MATCH(20,'LISTA DE PRECIOS'!$I$16:$I$1318,0)),"") | C35: =IFERROR(INDEX('LISTA DE PRECIOS'!C$16:C$1318,MATCH(20,'LISTA DE PRECIOS'!$I$16:$I$1318,0)),"") | D35: =IFERROR(INDEX('LISTA DE PRECIOS'!D$16:D$1318,MATCH(20,'LISTA DE PRECIOS'!$I$16:$I$1318,0)),"") | E35: =IFERROR(INDEX('LISTA DE PRECIOS'!E$16:E$1318,MATCH(20,'LISTA DE PRECIOS'!$I$16:$I$1318,0)),"") | F35: =IFERROR(INDEX('LISTA DE PRECIOS'!F$16:F$1318,MATCH(20,'LISTA DE PRECIOS'!$I$16:$I$1318,0)),"") | G35: =IFERROR(INDEX('LISTA DE PRECIOS'!G$16:G$1318,MATCH(20,'LISTA DE PRECIOS'!$I$16:$I$1318,0)),"") | H35: =IFERROR(INDEX('LISTA DE PRECIOS'!H$16:H$1318,MATCH(20,'LISTA DE PRECIOS'!$I$16:$I$1318,0)),"") | I35: =IF(OR(G35="",H35=""),"",G35*H35)
A36: =IFERROR(INDEX('LISTA DE PRECIOS'!A$16:A$1318,MATCH(21,'LISTA DE PRECIOS'!$I$16:$I$1318,0)),"") | B36: =IFERROR(INDEX('LISTA DE PRECIOS'!B$16:B$1318,MATCH(21,'LISTA DE PRECIOS'!$I$16:$I$1318,0)),"") | C36: =IFERROR(INDEX('LISTA DE PRECIOS'!C$16:C$1318,MATCH(21,'LISTA DE PRECIOS'!$I$16:$I$1318,0)),"") | D36: =IFERROR(INDEX('LISTA DE PRECIOS'!D$16:D$1318,MATCH(21,'LISTA DE PRECIOS'!$I$16:$I$1318,0)),"") | E36: =IFERROR(INDEX('LISTA DE PRECIOS'!E$16:E$1318,MATCH(21,'LISTA DE PRECIOS'!$I$16:$I$1318,0)),"") | F36: =IFERROR(INDEX('LISTA DE PRECIOS'!F$16:F$1318,MATCH(21,'LISTA DE PRECIOS'!$I$16:$I$1318,0)),"") | G36: =IFERROR(INDEX('LISTA DE PRECIOS'!G$16:G$1318,MATCH(21,'LISTA DE PRECIOS'!$I$16:$I$1318,0)),"") | H36: =IFERROR(INDEX('LISTA DE PRECIOS'!H$16:H$1318,MATCH(21,'LISTA DE PRECIOS'!$I$16:$I$1318,0)),"") | I36: =IF(OR(G36="",H36=""),"",G36*H36)
A37: =IFERROR(INDEX('LISTA DE PRECIOS'!A$16:A$1318,MATCH(22,'LISTA DE PRECIOS'!$I$16:$I$1318,0)),"") | B37: =IFERROR(INDEX('LISTA DE PRECIOS'!B$16:B$1318,MATCH(22,'LISTA DE PRECIOS'!$I$16:$I$1318,0)),"") | C37: =IFERROR(INDEX('LISTA DE PRECIOS'!C$16:C$1318,MATCH(22,'LISTA DE PRECIOS'!$I$16:$I$1318,0)),"") | D37: =IFERROR(INDEX('LISTA DE PRECIOS'!D$16:D$1318,MATCH(22,'LISTA DE PRECIOS'!$I$16:$I$1318,0)),"") | E37: =IFERROR(INDEX('LISTA DE PRECIOS'!E$16:E$1318,MATCH(22,'LISTA DE PRECIOS'!$I$16:$I$1318,0)),"") | F37: =IFERROR(INDEX('LISTA DE PRECIOS'!F$16:F$1318,MATCH(22,'LISTA DE PRECIOS'!$I$16:$I$1318,0)),"") | G37: =IFERROR(INDEX('LISTA DE PRECIOS'!G$16:G$1318,MATCH(22,'LISTA DE PRECIOS'!$I$16:$I$1318,0)),"") | H37: =IFERROR(INDEX('LISTA DE PRECIOS'!H$16:H$1318,MATCH(22,'LISTA DE PRECIOS'!$I$16:$I$1318,0)),"") | I37: =IF(OR(G37="",H37=""),"",G37*H37)
A38: =IFERROR(INDEX('LISTA DE PRECIOS'!A$16:A$1318,MATCH(23,'LISTA DE PRECIOS'!$I$16:$I$1318,0)),"") | B38: =IFERROR(INDEX('LISTA DE PRECIOS'!B$16:B$1318,MATCH(23,'LISTA DE PRECIOS'!$I$16:$I$1318,0)),"") | C38: =IFERROR(INDEX('LISTA DE PRECIOS'!C$16:C$1318,MATCH(23,'LISTA DE PRECIOS'!$I$16:$I$1318,0)),"") | D38: =IFERROR(INDEX('LISTA DE PRECIOS'!D$16:D$1318,MATCH(23,'LISTA DE PRECIOS'!$I$16:$I$1318,0)),"") | E38: =IFERROR(INDEX('LISTA DE PRECIOS'!E$16:E$1318,MATCH(23,'LISTA DE PRECIOS'!$I$16:$I$1318,0)),"") | F38: =IFERROR(INDEX('LISTA DE PRECIOS'!F$16:F$1318,MATCH(23,'LISTA DE PRECIOS'!$I$16:$I$1318,0)),"") | G38: =IFERROR(INDEX('LISTA DE PRECIOS'!G$16:G$1318,MATCH(23,'LISTA DE PRECIOS'!$I$16:$I$1318,0)),"") | H38: =IFERROR(INDEX('LISTA DE PRECIOS'!H$16:H$1318,MATCH(23,'LISTA DE PRECIOS'!$I$16:$I$1318,0)),"") | I38: =IF(OR(G38="",H38=""),"",G38*H38)
A39: =IFERROR(INDEX('LISTA DE PRECIOS'!A$16:A$1318,MATCH(24,'LISTA DE PRECIOS'!$I$16:$I$1318,0)),"") | B39: =IFERROR(INDEX('LISTA DE PRECIOS'!B$16:B$1318,MATCH(24,'LISTA DE PRECIOS'!$I$16:$I$1318,0)),"") | C39: =IFERROR(INDEX('LISTA DE PRECIOS'!C$16:C$1318,MATCH(24,'LISTA DE PRECIOS'!$I$16:$I$1318,0)),"") | D39: =IFERROR(INDEX('LISTA DE PRECIOS'!D$16:D$1318,MATCH(24,'LISTA DE PRECIOS'!$I$16:$I$1318,0)),"") | E39: =IFERROR(INDEX('LISTA DE PRECIOS'!E$16:E$1318,MATCH(24,'LISTA DE PRECIOS'!$I$16:$I$1318,0)),"") | F39: =IFERROR(INDEX('LISTA DE PRECIOS'!F$16:F$1318,MATCH(24,'LISTA DE PRECIOS'!$I$16:$I$1318,0)),"") | G39: =IFERROR(INDEX('LISTA DE PRECIOS'!G$16:G$1318,MATCH(24,'LISTA DE PRECIOS'!$I$16:$I$1318,0)),"") | H39: =IFERROR(INDEX('LISTA DE PRECIOS'!H$16:H$1318,MATCH(24,'LISTA DE PRECIOS'!$I$16:$I$1318,0)),"") | I39: =IF(OR(G39="",H39=""),"",G39*H39)
A40: =IFERROR(INDEX('LISTA DE PRECIOS'!A$16:A$1318,MATCH(25,'LISTA DE PRECIOS'!$I$16:$I$1318,0)),"") | B40: =IFERROR(INDEX('LISTA DE PRECIOS'!B$16:B$1318,MATCH(25,'LISTA DE PRECIOS'!$I$16:$I$1318,0)),"") | C40: =IFERROR(INDEX('LISTA DE PRECIOS'!C$16:C$1318,MATCH(25,'LISTA DE PRECIOS'!$I$16:$I$1318,0)),"") | D40: =IFERROR(INDEX('LISTA DE PRECIOS'!D$16:D$1318,MATCH(25,'LISTA DE PRECIOS'!$I$16:$I$1318,0)),"") | E40: =IFERROR(INDEX('LISTA DE PRECIOS'!E$16:E$1318,MATCH(25,'LISTA DE PRECIOS'!$I$16:$I$1318,0)),"") | F40: =IFERROR(INDEX('LISTA DE PRECIOS'!F$16:F$1318,MATCH(25,'LISTA DE PRECIOS'!$I$16:$I$1318,0)),"") | G40: =IFERROR(INDEX('LISTA DE PRECIOS'!G$16:G$1318,MATCH(25,'LISTA DE PRECIOS'!$I$16:$I$1318,0)),"") | H40: =IFERROR(INDEX('LISTA DE PRECIOS'!H$16:H$1318,MATCH(25,'LISTA DE PRECIOS'!$I$16:$I$1318,0)),"") | I40: =IF(OR(G40="",H40=""),"",G40*H40)
A41: =IFERROR(INDEX('LISTA DE PRECIOS'!A$16:A$1318,MATCH(26,'LISTA DE PRECIOS'!$I$16:$I$1318,0)),"") | B41: =IFERROR(INDEX('LISTA DE PRECIOS'!B$16:B$1318,MATCH(26,'LISTA DE PRECIOS'!$I$16:$I$1318,0)),"") | C41: =IFERROR(INDEX('LISTA DE PRECIOS'!C$16:C$1318,MATCH(26,'LISTA DE PRECIOS'!$I$16:$I$1318,0)),"") | D41: =IFERROR(INDEX('LISTA DE PRECIOS'!D$16:D$1318,MATCH(26,'LISTA DE PRECIOS'!$I$16:$I$1318,0)),"") | E41: =IFERROR(INDEX('LISTA DE PRECIOS'!E$16:E$1318,MATCH(26,'LISTA DE PRECIOS'!$I$16:$I$1318,0)),"") | F41: =IFERROR(INDEX('LISTA DE PRECIOS'!F$16:F$1318,MATCH(26,'LISTA DE PRECIOS'!$I$16:$I$1318,0)),"") | G41: =IFERROR(INDEX('LISTA DE PRECIOS'!G$16:G$1318,MATCH(26,'LISTA DE PRECIOS'!$I$16:$I$1318,0)),"") | H41: =IFERROR(INDEX('LISTA DE PRECIOS'!H$16:H$1318,MATCH(26,'LISTA DE PRECIOS'!$I$16:$I$1318,0)),"") | I41: =IF(OR(G41="",H41=""),"",G41*H41)
A42: =IFERROR(INDEX('LISTA DE PRECIOS'!A$16:A$1318,MATCH(27,'LISTA DE PRECIOS'!$I$16:$I$1318,0)),"") | B42: =IFERROR(INDEX('LISTA DE PRECIOS'!B$16:B$1318,MATCH(27,'LISTA DE PRECIOS'!$I$16:$I$1318,0)),"") | C42: =IFERROR(INDEX('LISTA DE PRECIOS'!C$16:C$1318,MATCH(27,'LISTA DE PRECIOS'!$I$16:$I$1318,0)),"") | D42: =IFERROR(INDEX('LISTA DE PRECIOS'!D$16:D$1318,MATCH(27,'LISTA DE PRECIOS'!$I$16:$I$1318,0)),"") | E42: =IFERROR(INDEX('LISTA DE PRECIOS'!E$16:E$1318,MATCH(27,'LISTA DE PRECIOS'!$I$16:$I$1318,0)),"") | F42: =IFERROR(INDEX('LISTA DE PRECIOS'!F$16:F$1318,MATCH(27,'LISTA DE PRECIOS'!$I$16:$I$1318,0)),"") | G42: =IFERROR(INDEX('LISTA DE PRECIOS'!G$16:G$1318,MATCH(27,'LISTA DE PRECIOS'!$I$16:$I$1318,0)),"") | H42: =IFERROR(INDEX('LISTA DE PRECIOS'!H$16:H$1318,MATCH(27,'LISTA DE PRECIOS'!$I$16:$I$1318,0)),"") | I42: =IF(OR(G42="",H42=""),"",G42*H42)
A43: =IFERROR(INDEX('LISTA DE PRECIOS'!A$16:A$1318,MATCH(28,'LISTA DE PRECIOS'!$I$16:$I$1318,0)),"") | B43: =IFERROR(INDEX('LISTA DE PRECIOS'!B$16:B$1318,MATCH(28,'LISTA DE PRECIOS'!$I$16:$I$1318,0)),"") | C43: =IFERROR(INDEX('LISTA DE PRECIOS'!C$16:C$1318,MATCH(28,'LISTA DE PRECIOS'!$I$16:$I$1318,0)),"") | D43: =IFERROR(INDEX('LISTA DE PRECIOS'!D$16:D$1318,MATCH(28,'LISTA DE PRECIOS'!$I$16:$I$1318,0)),"") | E43: =IFERROR(INDEX('LISTA DE PRECIOS'!E$16:E$1318,MATCH(28,'LISTA DE PRECIOS'!$I$16:$I$1318,0)),"") | F43: =IFERROR(INDEX('LISTA DE PRECIOS'!F$16:F$1318,MATCH(28,'LISTA DE PRECIOS'!$I$16:$I$1318,0)),"") | G43: =IFERROR(INDEX('LISTA DE PRECIOS'!G$16:G$1318,MATCH(28,'LISTA DE PRECIOS'!$I$16:$I$1318,0)),"") | H43: =IFERROR(INDEX('LISTA DE PRECIOS'!H$16:H$1318,MATCH(28,'LISTA DE PRECIOS'!$I$16:$I$1318,0)),"") | I43: =IF(OR(G43="",H43=""),"",G43*H43)
A44: =IFERROR(INDEX('LISTA DE PRECIOS'!A$16:A$1318,MATCH(29,'LISTA DE PRECIOS'!$I$16:$I$1318,0)),"") | B44: =IFERROR(INDEX('LISTA DE PRECIOS'!B$16:B$1318,MATCH(29,'LISTA DE PRECIOS'!$I$16:$I$1318,0)),"") | C44: =IFERROR(INDEX('LISTA DE PRECIOS'!C$16:C$1318,MATCH(29,'LISTA DE PRECIOS'!$I$16:$I$1318,0)),"") | D44: =IFERROR(INDEX('LISTA DE PRECIOS'!D$16:D$1318,MATCH(29,'LISTA DE PRECIOS'!$I$16:$I$1318,0)),"") | E44: =IFERROR(INDEX('LISTA DE PRECIOS'!E$16:E$1318,MATCH(29,'LISTA DE PRECIOS'!$I$16:$I$1318,0)),"") | F44: =IFERROR(INDEX('LISTA DE PRECIOS'!F$16:F$1318,MATCH(29,'LISTA DE PRECIOS'!$I$16:$I$1318,0)),"") | G44: =IFERROR(INDEX('LISTA DE PRECIOS'!G$16:G$1318,MATCH(29,'LISTA DE PRECIOS'!$I$16:$I$1318,0)),"") | H44: =IFERROR(INDEX('LISTA DE PRECIOS'!H$16:H$1318,MATCH(29,'LISTA DE PRECIOS'!$I$16:$I$1318,0)),"") | I44: =IF(OR(G44="",H44=""),"",G44*H44)
A45: =IFERROR(INDEX('LISTA DE PRECIOS'!A$16:A$1318,MATCH(30,'LISTA DE PRECIOS'!$I$16:$I$1318,0)),"") | B45: =IFERROR(INDEX('LISTA DE PRECIOS'!B$16:B$1318,MATCH(30,'LISTA DE PRECIOS'!$I$16:$I$1318,0)),"") | C45: =IFERROR(INDEX('LISTA DE PRECIOS'!C$16:C$1318,MATCH(30,'LISTA DE PRECIOS'!$I$16:$I$1318,0)),"") | D45: =IFERROR(INDEX('LISTA DE PRECIOS'!D$16:D$1318,MATCH(30,'LISTA DE PRECIOS'!$I$16:$I$1318,0)),"") | E45: =IFERROR(INDEX('LISTA DE PRECIOS'!E$16:E$1318,MATCH(30,'LISTA DE PRECIOS'!$I$16:$I$1318,0)),"") | F45: =IFERROR(INDEX('LISTA DE PRECIOS'!F$16:F$1318,MATCH(30,'LISTA DE PRECIOS'!$I$16:$I$1318,0)),"") | G45: =IFERROR(INDEX('LISTA DE PRECIOS'!G$16:G$1318,MATCH(30,'LISTA DE PRECIOS'!$I$16:$I$1318,0)),"") | H45: =IFERROR(INDEX('LISTA DE PRECIOS'!H$16:H$1318,MATCH(30,'LISTA DE PRECIOS'!$I$16:$I$1318,0)),"") | I45: =IF(OR(G45="",H45=""),"",G45*H45)
A46: =IFERROR(INDEX('LISTA DE PRECIOS'!A$16:A$1318,MATCH(31,'LISTA DE PRECIOS'!$I$16:$I$1318,0)),"") | B46: =IFERROR(INDEX('LISTA DE PRECIOS'!B$16:B$1318,MATCH(31,'LISTA DE PRECIOS'!$I$16:$I$1318,0)),"") | C46: =IFERROR(INDEX('LISTA DE PRECIOS'!C$16:C$1318,MATCH(31,'LISTA DE PRECIOS'!$I$16:$I$1318,0)),"") | D46: =IFERROR(INDEX('LISTA DE PRECIOS'!D$16:D$1318,MATCH(31,'LISTA DE PRECIOS'!$I$16:$I$1318,0)),"") | E46: =IFERROR(INDEX('LISTA DE PRECIOS'!E$16:E$1318,MATCH(31,'LISTA DE PRECIOS'!$I$16:$I$1318,0)),"") | F46: =IFERROR(INDEX('LISTA DE PRECIOS'!F$16:F$1318,MATCH(31,'LISTA DE PRECIOS'!$I$16:$I$1318,0)),"") | G46: =IFERROR(INDEX('LISTA DE PRECIOS'!G$16:G$1318,MATCH(31,'LISTA DE PRECIOS'!$I$16:$I$1318,0)),"") | H46: =IFERROR(INDEX('LISTA DE PRECIOS'!H$16:H$1318,MATCH(31,'LISTA DE PRECIOS'!$I$16:$I$1318,0)),"") | I46: =IF(OR(G46="",H46=""),"",G46*H46)
A47: =IFERROR(INDEX('LISTA DE PRECIOS'!A$16:A$1318,MATCH(32,'LISTA DE PRECIOS'!$I$16:$I$1318,0)),"") | B47: =IFERROR(INDEX('LISTA DE PRECIOS'!B$16:B$1318,MATCH(32,'LISTA DE PRECIOS'!$I$16:$I$1318,0)),"") | C47: =IFERROR(INDEX('LISTA DE PRECIOS'!C$16:C$1318,MATCH(32,'LISTA DE PRECIOS'!$I$16:$I$1318,0)),"") | D47: =IFERROR(INDEX('LISTA DE PRECIOS'!D$16:D$1318,MATCH(32,'LISTA DE PRECIOS'!$I$16:$I$1318,0)),"") | E47: =IFERROR(INDEX('LISTA DE PRECIOS'!E$16:E$1318,MATCH(32,'LISTA DE PRECIOS'!$I$16:$I$1318,0)),"") | F47: =IFERROR(INDEX('LISTA DE PRECIOS'!F$16:F$1318,MATCH(32,'LISTA DE PRECIOS'!$I$16:$I$1318,0)),"") | G47: =IFERROR(INDEX('LISTA DE PRECIOS'!G$16:G$1318,MATCH(32,'LISTA DE PRECIOS'!$I$16:$I$1318,0)),"") | H47: =IFERROR(INDEX('LISTA DE PRECIOS'!H$16:H$1318,MATCH(32,'LISTA DE PRECIOS'!$I$16:$I$1318,0)),"") | I47: =IF(OR(G47="",H47=""),"",G47*H47)
A48: =IFERROR(INDEX('LISTA DE PRECIOS'!A$16:A$1318,MATCH(33,'LISTA DE PRECIOS'!$I$16:$I$1318,0)),"") | B48: =IFERROR(INDEX('LISTA DE PRECIOS'!B$16:B$1318,MATCH(33,'LISTA DE PRECIOS'!$I$16:$I$1318,0)),"") | C48: =IFERROR(INDEX('LISTA DE PRECIOS'!C$16:C$1318,MATCH(33,'LISTA DE PRECIOS'!$I$16:$I$1318,0)),"") | D48: =IFERROR(INDEX('LISTA DE PRECIOS'!D$16:D$1318,MATCH(33,'LISTA DE PRECIOS'!$I$16:$I$1318,0)),"") | E48: =IFERROR(INDEX('LISTA DE PRECIOS'!E$16:E$1318,MATCH(33,'LISTA DE PRECIOS'!$I$16:$I$1318,0)),"") | F48: =IFERROR(INDEX('LISTA DE PRECIOS'!F$16:F$1318,MATCH(33,'LISTA DE PRECIOS'!$I$16:$I$1318,0)),"") | G48: =IFERROR(INDEX('LISTA DE PRECIOS'!G$16:G$1318,MATCH(33,'LISTA DE PRECIOS'!$I$16:$I$1318,0)),"") | H48: =IFERROR(INDEX('LISTA DE PRECIOS'!H$16:H$1318,MATCH(33,'LISTA DE PRECIOS'!$I$16:$I$1318,0)),"") | I48: =IF(OR(G48="",H48=""),"",G48*H48)
A49: =IFERROR(INDEX('LISTA DE PRECIOS'!A$16:A$1318,MATCH(34,'LISTA DE PRECIOS'!$I$16:$I$1318,0)),"") | B49: =IFERROR(INDEX('LISTA DE PRECIOS'!B$16:B$1318,MATCH(34,'LISTA DE PRECIOS'!$I$16:$I$1318,0)),"") | C49: =IFERROR(INDEX('LISTA DE PRECIOS'!C$16:C$1318,MATCH(34,'LISTA DE PRECIOS'!$I$16:$I$1318,0)),"") | D49: =IFERROR(INDEX('LISTA DE PRECIOS'!D$16:D$1318,MATCH(34,'LISTA DE PRECIOS'!$I$16:$I$1318,0)),"") | E49: =IFERROR(INDEX('LISTA DE PRECIOS'!E$16:E$1318,MATCH(34,'LISTA DE PRECIOS'!$I$16:$I$1318,0)),"") | F49: =IFERROR(INDEX('LISTA DE PRECIOS'!F$16:F$1318,MATCH(34,'LISTA DE PRECIOS'!$I$16:$I$1318,0)),"") | G49: =IFERROR(INDEX('LISTA DE PRECIOS'!G$16:G$1318,MATCH(34,'LISTA DE PRECIOS'!$I$16:$I$1318,0)),"") | H49: =IFERROR(INDEX('LISTA DE PRECIOS'!H$16:H$1318,MATCH(34,'LISTA DE PRECIOS'!$I$16:$I$1318,0)),"") | I49: =IF(OR(G49="",H49=""),"",G49*H49)
...
